<?xml version="1.0"?>

<robot name ="arm" xmlns:xacro="http/www.ros.org/wiki/xacro">

    <link name ="Base_link">
        <visual>
            <origin xyz="0 0 0" rpy="0 0 0"></origin>
            <geometry>
                <box size = "1 1 0.2"/>                      
            </geometry>
            <material name="Cyan">
                <color rgba="0.6 1.0 1.0 1.0"/>
            </material>
        </visual>
        <inertial>

            <mass value="10"/>
            <origin xyz="0 0 0" rpy=" 0 0 0"/>
            <inertia
                ixx="0.86" ixy="0" ixz="0"
                iyy="1.6" iyz="0"
                izz="1.6"
            />
      
         </inertial>
      
         <collision name='collision'>
            <geometry>
              <box size="1 1 0.2"/>
            </geometry>
         </collision>
    </link>

    <joint name="Base_link1_joint" type = "revolute">
        <axis xyz="0 0 1"/>
        <limit effort ="1000.0" lower ="-3.14" upper="3.14" velocity ="0.5"/>
        <origin xyz="0 0 0.1" rpy="0 0 0"/>
        <parent link="Base_link"/>
        <child link="Link_1"/>      
    </joint>
    
    <link name ="Link_1">
        <visual>
            <origin xyz="0 0 0.5" rpy="1.5707 1.5707 0"></origin>
            <geometry>
                <box size = "1 0.5 0.1"/>                      
            </geometry>
            <material name="Red">
                <color rgba="0.9 1.0 0.4 1.0"/>
            </material>
        </visual>
        <inertial>

            <mass value="1"/>
            <origin xyz="0 0 0" rpy=" 0 0 0"/>
            <inertia
                ixx="0.216" ixy="0" ixz="0"
                iyy="0.104" iyz="0"
                izz="0.104"
            />
      
         </inertial>
      
         <collision name='collision'>
            <geometry>
              <box size="1 0.5 0.1"/>
            </geometry>
         </collision>
    </link>

    <joint name="Link1_Link2_joint" type="revolute">
        <axis xyz ="0 1 0"/>
        <limit effort ="1000.0" lower ="-3.14" upper="3.14" velocity ="0.5"/>
        <origin xyz="0 0.05 0.8" rpy="0 0 0"/>
        <parent link="Link_1"/>
        <child link="Link_2"/>      
    </joint>

    <link name ="Link_2">
        <visual>
            <origin xyz="0 0.05 0.5" rpy="1.5707 1.5707 0"></origin>
            <geometry>
                <box size = "1 0.5 0.1"/>                      
            </geometry>
            <material name="White">
                <color rgba="0.5 0.6 0.45 1.0"/>
            </material>
        </visual>
        <inertial>

            <mass value="1"/>
            <origin xyz="0 0 0" rpy=" 0 0 0"/>
            <inertia
                ixx="0.216" ixy="0" ixz="0"
                iyy="0.104" iyz="0"
                izz="0.104"
            />
      
         </inertial>
      
         <collision name='collision'>
            <geometry>
              <box size="1 0.5 0.1"/>
            </geometry>
         </collision>
    </link>

    <joint name="Link2_Link3_joint" type="revolute">
        <axis xyz ="0 1 0"/>
        <limit effort ="1000.0" lower ="-3.14" upper="3.14" velocity ="0.5"/>
        <origin xyz="0 -0.05 0.8" rpy="0 0 0"/>
        <parent link="Link_2"/>
        <child link="Link_3"/>      
    </joint>
    <link name ="Link_3">
        <visual>
            <origin xyz="0 0 0.3" rpy="1.5707 1.5707 0"></origin>
            <geometry>
                <box size = "1 0.5 0.1"/>                      
            </geometry>
            <material name="blue">
                <color rgba="0.3 0.2 0.1 1.0"/>
            </material>
        </visual>
        <inertial>

            <mass value="1"/>
            <origin xyz="0 0 0" rpy=" 0 0 0"/>
            <inertia
                ixx="0.216" ixy="0" ixz="0"
                iyy="0.104" iyz="0"
                izz="0.104"
            />
      
         </inertial>
      
         <collision name='collision'>
            <geometry>
              <box size="1 0.5 0.1"/>
            </geometry>
         </collision>
    </link>
    
</robot>